Traceback (most recent call last):
  File "MS_Total_Software.py", line 129, in run_full_analysis
    with open(f"./bin/All_proteins_{Spiecies}_{Owner_ID}_{id}.json", 'r') as myfile:
FileNotFoundError: [Errno 2] No such file or directory: './bin/All_proteins_MOUSE_2_150.json'

During handling of the above exception, another exception occurred:

Traceback (most recent call last):
  File "MS_Total_Software.py", line 146, in run_full_analysis
    All_proteins[Gene][Type].append(Protein)
KeyError: 'undefined'

During handling of the above exception, another exception occurred:

Traceback (most recent call last):
  File "MS_Total_Software.py", line 149, in run_full_analysis
    All_proteins[Gene][Type]=[]
KeyError: 'undefined'

During handling of the above exception, another exception occurred:

Traceback (most recent call last):
  File "MS_Total_Software.py", line 413, in <module>
    retrieve_mysql_data(id_to_process)
  File "MS_Total_Software.py", line 339, in retrieve_mysql_data
    run_full_analysis(Domain_types, Protein_peptides, experiment_feed,Owner_ID,id,paired=Paired, Spiecies=Spiecies)
  File "MS_Total_Software.py", line 153, in run_full_analysis
    All_proteins[Gene][Type]=[]
UnboundLocalError: local variable 'Type' referenced before assignment
