Traceback (most recent call last):
  File "/mnt/iusers01/mhs01/mbchpmo2/.conda/envs/myenv/lib/python3.6/site-packages/mysql/connector/network.py", line 509, in open_connection
    self.sock.connect(sockaddr)
TimeoutError: [Errno 110] Connection timed out

During handling of the above exception, another exception occurred:

Traceback (most recent call last):
  File "MS_Total_Software.py", line 236, in <module>
    retrieve_mysql_data()
  File "MS_Total_Software.py", line 203, in retrieve_mysql_data
    auth_plugin='mysql_native_password')
  File "/mnt/iusers01/mhs01/mbchpmo2/.conda/envs/myenv/lib/python3.6/site-packages/mysql/connector/__init__.py", line 179, in connect
    return MySQLConnection(*args, **kwargs)
  File "/mnt/iusers01/mhs01/mbchpmo2/.conda/envs/myenv/lib/python3.6/site-packages/mysql/connector/connection.py", line 95, in __init__
    self.connect(**kwargs)
  File "/mnt/iusers01/mhs01/mbchpmo2/.conda/envs/myenv/lib/python3.6/site-packages/mysql/connector/abstracts.py", line 716, in connect
    self._open_connection()
  File "/mnt/iusers01/mhs01/mbchpmo2/.conda/envs/myenv/lib/python3.6/site-packages/mysql/connector/connection.py", line 206, in _open_connection
    self._socket.open_connection()
  File "/mnt/iusers01/mhs01/mbchpmo2/.conda/envs/myenv/lib/python3.6/site-packages/mysql/connector/network.py", line 512, in open_connection
    errno=2003, values=(self.get_address(), _strioerror(err)))
mysql.connector.errors.InterfaceError: 2003: Can't connect to MySQL server on '130.88.96.141:3307' (110 Connection timed out)
